Workbook

Sheet Assumptions
A1: Assumption | B1: Value
A2: Annual Operating Budget | B2: 2400000 | D2: =_xlfn.CONCAT(A2,CHAR(10), TEXT(B2,"$#,##0")) -> Annual Operating Budget $2,400,000
A3: Monthly Operating Budget | B3: =B2/12 -> 200000
A4: Annual Salary Budget | B4: 1440000
A5: Annual Overtime Budget | B5: 120000
A6: Annual Benefits Budget | B6: 360000
A7: Annual Technology Budget | B7: 240000
A8: Annual Facilities Budget | B8: 240000
A9: Annual Workload Growth Assumption | B9: 0.1
A10: Expected Salary Increase | B10: 0.03
A11: Employer Benefits Rate | B11: 0.25
A13: Budget Validation | B13: =B2-SUM(B4:B8) -> 0
A15: Scenario salary increases are modeled without additional changes to employer benefit costs.

Sheet Budget Vs Actual
A1: Month | B1: Expense Category | C1: Budget | D1: Actual | E1: Variance ($) | F1: Variance (%) | G1: Status | I1: Expense Category | J1: Annual Budget | K1: Actual Spending | L1: Variance ($) | M1: Variance (%)
A2: January | B2: Salaries and Wages | C2: 120000 | D2: 121600 | E2: =D2-C2 -> 1600 | F2: =IFERROR(E2/C2,0) -> 0.013333333 | G2: =IF(E2>0,"Over Budget",IF(E2<0,"Under Budget","On Budget")) -> Over Budget | I2: Overtime | J2: =SUMIF($B$2:$B$72,I2,$C$2:$C$72) -> 120000 | K2: =SUMIF($B$2:$B$72,I2,$D$2:$D$72) -> 185100 | L2: =SUMIF($B$2:$B$72,I2,$E$2:$E$72) -> 65100 | M2: =IFERROR(L2/J2,0) -> 0.5425
A3: January | B3: Overtime | C3: 10000 | D3: 12400 | E3: =D3-C3 -> 2400 | F3: =IFERROR(E3/C3,0) -> 0.24 | G3: =IF(E3>0,"Over Budget",IF(E3<0,"Under Budget","On Budget")) -> Over Budget | I3: Salaries and Wages | J3: =SUMIF($B$2:$B$72,I3,$C$2:$C$72) -> 1440000 | K3: =SUMIF($B$2:$B$72,I3,$D$2:$D$72) -> 1489800 | L3: =SUMIF($B$2:$B$72,I3,$E$2:$E$72) -> 49800 | M3: =IFERROR(L3/J3,0) -> 0.034583333
A4: January | B4: Benefits | C4: 30000 | D4: 30450 | E4: =D4-C4 -> 450 | F4: =IFERROR(E4/C4,0) -> 0.015 | G4: =IF(E4>0,"Over Budget",IF(E4<0,"Under Budget","On Budget")) -> Over Budget | I4: Technology | J4: =SUMIF($B$2:$B$72,I4,$C$2:$C$72) -> 240000 | K4: =SUMIF($B$2:$B$72,I4,$D$2:$D$72) -> 256150 | L4: =SUMIF($B$2:$B$72,I4,$E$2:$E$72) -> 16150 | M4: =IFERROR(L4/J4,0) -> 0.067291667
A5: January | B5: Technology | C5: 20000 | D5: 19200 | E5: =D5-C5 -> -800 | F5: =IFERROR(E5/C5,0) -> -0.04 | G5: =IF(E5>0,"Over Budget",IF(E5<0,"Under Budget","On Budget")) -> Under Budget | I5: Benefits | J5: =SUMIF($B$2:$B$72,I5,$C$2:$C$72) -> 360000 | K5: =SUMIF($B$2:$B$72,I5,$D$2:$D$72) -> 373575 | L5: =SUMIF($B$2:$B$72,I5,$E$2:$E$72) -> 13575 | M5: =IFERROR(L5/J5,0) -> 0.037708333
A6: January | B6: Facilities | C6: 20000 | D6: 20600 | E6: =D6-C6 -> 600 | F6: =IFERROR(E6/C6,0) -> 0.03 | G6: =IF(E6>0,"Over Budget",IF(E6<0,"Under Budget","On Budget")) -> Over Budget | I6: Facilities | J6: =SUMIF($B$2:$B$72,I6,$C$2:$C$72) -> 240000 | K6: =SUMIF($B$2:$B$72,I6,$D$2:$D$72) -> 252800 | L6: =SUMIF($B$2:$B$72,I6,$E$2:$E$72) -> 12800 | M6: =IFERROR(L6/J6,0) -> 0.053333333
A7: Jan Total | C7: =SUM(C2:C6) -> 200000 | D7: =SUM(D2:D6) -> 204250 | E7: =D7-C7 -> 4250 | F7: =IFERROR(E7/C7,0) -> 0.02125 | G7: =IF(E7>0,"Over Budget",IF(E7<0,"Under Budget","On Budget")) -> Over Budget | I7: Annual Totals | J7: =SUM(J2:J6) -> 2400000 | K7: =SUM(K2:K6) -> 2557425 | L7: =SUM(L2:L6) -> 157425 | M7: =IFERROR(L7/J7,0) -> 0.06559375 | O7: =_xlfn.CONCAT("Actual Spending",CHAR(10),TEXT(K7,"$##,#00")) -> Actual Spending $2,557,425
A8: February | B8: Salaries and Wages | C8: 120000 | D8: 119500 | E8: =D8-C8 -> -500 | F8: =IFERROR(E8/C8,0) -> -0.0041666667 | G8: =IF(E8>0,"Over Budget",IF(E8<0,"Under Budget","On Budget")) -> Under Budget | O8: =_xlfn.CONCAT("Budget Overrun",CHAR(10),TEXT(L7,"$##,#00")) -> Budget Overrun $157,425
A9: February | B9: Overtime | C9: 10000 | D9: 11200 | E9: =D9-C9 -> 1200 | F9: =IFERROR(E9/C9,0) -> 0.12 | G9: =IF(E9>0,"Over Budget",IF(E9<0,"Under Budget","On Budget")) -> Over Budget | O9: =_xlfn.CONCAT("Budget Variance",CHAR(10),TEXT(M7,"0.00%")) -> Budget Variance 6.56%
A10: February | B10: Benefits | C10: 30000 | D10: 29875 | E10: =D10-C10 -> -125 | F10: =IFERROR(E10/C10,0) -> -0.0041666667 | G10: =IF(E10>0,"Over Budget",IF(E10<0,"Under Budget","On Budget")) -> Under Budget | I10: Month | J10: Budget | K10: Actual | L10: Variance
A11: February | B11: Technology | C11: 20000 | D11: 21400 | E11: =D11-C11 -> 1400 | F11: =IFERROR(E11/C11,0) -> 0.07 | G11: =IF(E11>0,"Over Budget",IF(E11<0,"Under Budget","On Budget")) -> Over Budget | I11: January | J11: =C7 -> 200000 | K11: =D7 -> 204250 | L11: =E7 -> 4250
A12: February | B12: Facilities | C12: 20000 | D12: 19300 | E12: =D12-C12 -> -700 | F12: =IFERROR(E12/C12,0) -> -0.035 | G12: =IF(E12>0,"Over Budget",IF(E12<0,"Under Budget","On Budget")) -> Under Budget | I12: February | J12: =C13 -> 200000 | K12: =D13 -> 201275 | L12: =E13 -> 1275
A13: Feb Total | C13: =SUM(C8:C12) -> 200000 | D13: =SUM(D8:D12) -> 201275 | E13: =D13-C13 -> 1275 | F13: =IFERROR(E13/C13,0) -> 0.006375 | G13: =IF(E13>0,"Over Budget",IF(E13<0,"Under Budget","On Budget")) -> Over Budget | I13: March | J13: =C19 -> 200000 | K13: =D19 -> 208650 | L13: =E19 -> 8650
A14: March | B14: Salaries and Wages | C14: 120000 | D14: 123200 | E14: =D14-C14 -> 3200 | F14: =IFERROR(E14/C14,0) -> 0.026666667 | G14: =IF(E14>0,"Over Budget",IF(E14<0,"Under Budget","On Budget")) -> Over Budget | I14: April | J14: =C25 -> 200000 | K14: =D25 -> 203950 | L14: =E25 -> 3950
A15: March | B15: Overtime | C15: 10000 | D15: 13800 | E15: =D15-C15 -> 3800 | F15: =IFERROR(E15/C15,0) -> 0.38 | G15: =IF(E15>0,"Over Budget",IF(E15<0,"Under Budget","On Budget")) -> Over Budget | I15: May | J15: =C31 -> 200000 | K15: =D31 -> 209300 | L15: =E31 -> 9300
A16: March | B16: Benefits | C16: 30000 | D16: 30800 | E16: =D16-C16 -> 800 | F16: =IFERROR(E16/C16,0) -> 0.026666667 | G16: =IF(E16>0,"Over Budget",IF(E16<0,"Under Budget","On Budget")) -> Over Budget | I16: June | J16: =C37 -> 200000 | K16: =D37 -> 212400 | L16: =E37 -> 12400
A17: March | B17: Technology | C17: 20000 | D17: 19750 | E17: =D17-C17 -> -250 | F17: =IFERROR(E17/C17,0) -> -0.0125 | G17: =IF(E17>0,"Over Budget",IF(E17<0,"Under Budget","On Budget")) -> Under Budget | I17: July | J17: =C43 -> 200000 | K17: =D43 -> 211350 | L17: =E43 -> 11350
A18: March | B18: Facilities | C18: 20000 | D18: 21100 | E18: =D18-C18 -> 1100 | F18: =IFERROR(E18/C18,0) -> 0.055 | G18: =IF(E18>0,"Over Budget",IF(E18<0,"Under Budget","On Budget")) -> Over Budget | I18: August | J18: =C49 -> 200000 | K18: =D49 -> 216100 | L18: =E49 -> 16100
A19: Mar Total | C19: =SUM(C14:C18) -> 200000 | D19: =SUM(D14:D18) -> 208650 | E19: =D19-C19 -> 8650 | F19: =IFERROR(E19/C19,0) -> 0.04325 | G19: =IF(E19>0,"Over Budget",IF(E19<0,"Under Budget","On Budget")) -> Over Budget | I19: September | J19: =C55 -> 200000 | K19: =D55 -> 220700 | L19: =E55 -> 20700
A20: April | B20: Salaries and Wages | C20: 120000 | D20: 121400 | E20: =D20-C20 -> 1400 | F20: =IFERROR(E20/C20,0) -> 0.011666667 | G20: =IF(E20>0,"Over Budget",IF(E20<0,"Under Budget","On Budget")) -> Over Budget | I20: October | J20: =C61 -> 200000 | K20: =D61 -> 217050 | L20: =E61 -> 17050
A21: April | B21: Overtime | C21: 10000 | D21: 11900 | E21: =D21-C21 -> 1900 | F21: =IFERROR(E21/C21,0) -> 0.19 | G21: =IF(E21>0,"Over Budget",IF(E21<0,"Under Budget","On Budget")) -> Over Budget | I21: November | J21: =C67 -> 200000 | K21: =D67 -> 224100 | L21: =E67 -> 24100
A22: April | B22: Benefits | C22: 30000 | D22: 30350 | E22: =D22-C22 -> 350 | F22: =IFERROR(E22/C22,0) -> 0.011666667 | G22: =IF(E22>0,"Over Budget",IF(E22<0,"Under Budget","On Budget")) -> Over Budget | I22: December | J22: =C73 -> 200000 | K22: =D73 -> 228300 | L22: =E73 -> 28300
A23: April | B23: Technology | C23: 20000 | D23: 20500 | E23: =D23-C23 -> 500 | F23: =IFERROR(E23/C23,0) -> 0.025 | G23: =IF(E23>0,"Over Budget",IF(E23<0,"Under Budget","On Budget")) -> Over Budget
A24: April | B24: Facilities | C24: 20000 | D24: 19800 | E24: =D24-C24 -> -200 | F24: =IFERROR(E24/C24,0) -> -0.01 | G24: =IF(E24>0,"Over Budget",IF(E24<0,"Under Budget","On Budget")) -> Under Budget
A25: Apr Total | C25: =SUM(C20:C24) -> 200000 | D25: =SUM(D20:D24) -> 203950 | E25: =D25-C25 -> 3950 | F25: =IFERROR(E25/C25,0) -> 0.01975 | G25: =IF(E25>0,"Over Budget",IF(E25<0,"Under Budget","On Budget")) -> Over Budget
A26: May | B26: Salaries and Wages | C26: 120000 | D26: 122800 | E26: =D26-C26 -> 2800 | F26: =IFERROR(E26/C26,0) -> 0.023333333 | G26: =IF(E26>0,"Over Budget",IF(E26<0,"Under Budget","On Budget")) -> Over Budget
A27: May | B27: Overtime | C27: 10000 | D27: 14200 | E27: =D27-C27 -> 4200 | F27: =IFERROR(E27/C27,0) -> 0.42 | G27: =IF(E27>0,"Over Budget",IF(E27<0,"Under Budget","On Budget")) -> Over Budget
A28: May | B28: Benefits | C28: 30000 | D28: 30700 | E28: =D28-C28 -> 700 | F28: =IFERROR(E28/C28,0) -> 0.023333333 | G28: =IF(E28>0,"Over Budget",IF(E28<0,"Under Budget","On Budget")) -> Over Budget
A29: May | B29: Technology | C29: 20000 | D29: 21200 | E29: =D29-C29 -> 1200 | F29: =IFERROR(E29/C29,0) -> 0.06 | G29: =IF(E29>0,"Over Budget",IF(E29<0,"Under Budget","On Budget")) -> Over Budget
A30: May | B30: Facilities | C30: 20000 | D30: 20400 | E30: =D30-C30 -> 400 | F30: =IFERROR(E30/C30,0) -> 0.02 | G30: =IF(E30>0,"Over Budget",IF(E30<0,"Under Budget","On Budget")) -> Over Budget
A31: May Total | C31: =SUM(C26:C30) -> 200000 | D31: =SUM(D26:D30) -> 209300 | E31: =D31-C31 -> 9300 | F31: =IFERROR(E31/C31,0) -> 0.0465 | G31: =IF(E31>0,"Over Budget",IF(E31<0,"Under Budget","On Budget")) -> Over Budget
A32: June | B32: Salaries and Wages | C32: 120000 | D32: 124500 | E32: =D32-C32 -> 4500 | F32: =IFERROR(E32/C32,0) -> 0.0375 | G32: =IF(E32>0,"Over Budget",IF(E32<0,"Under Budget","On Budget")) -> Over Budget
A33: =$A$32 -> June | B33: Overtime | C33: 10000 | D33: 15800 | E33: =D33-C33 -> 5800 | F33: =IFERROR(E33/C33,0) -> 0.58 | G33: =IF(E33>0,"Over Budget",IF(E33<0,"Under Budget","On Budget")) -> Over Budget
A34: =$A$32 -> June | B34: Benefits | C34: 30000 | D34: 31200 | E34: =D34-C34 -> 1200 | F34: =IFERROR(E34/C34,0) -> 0.04 | G34: =IF(E34>0,"Over Budget",IF(E34<0,"Under Budget","On Budget")) -> Over Budget
A35: =$A$32 -> June | B35: Technology | C35: 20000 | D35: 19800 | E35: =D35-C35 -> -200 | F35: =IFERROR(E35/C35,0) -> -0.01 | G35: =IF(E35>0,"Over Budget",IF(E35<0,"Under Budget","On Budget")) -> Under Budget
A36: =$A$32 -> June | B36: Facilities | C36: 20000 | D36: 21100 | E36: =D36-C36 -> 1100 | F36: =IFERROR(E36/C36,0) -> 0.055 | G36: =IF(E36>0,"Over Budget",IF(E36<0,"Under Budget","On Budget")) -> Over Budget
A37: June Total | C37: =SUM(C32:C36) -> 200000 | D37: =SUM(D32:D36) -> 212400 | E37: =D37-C37 -> 12400 | F37: =IFERROR(E37/C37,0) -> 0.062 | G37: =IF(E37>0,"Over Budget",IF(E37<0,"Under Budget","On Budget")) -> Over Budget
A38: July | B38: Salaries and Wages | C38: 120000 | D38: 123700 | E38: =D38-C38 -> 3700 | F38: =IFERROR(E38/C38,0) -> 0.030833333 | G38: =IF(E38>0,"Over Budget",IF(E38<0,"Under Budget","On Budget")) -> Over Budget
A39: =$A$38 -> July | B39: Overtime | C39: 10000 | D39: 13900 | E39: =D39-C39 -> 3900 | F39: =IFERROR(E39/C39,0) -> 0.39 | G39: =IF(E39>0,"Over Budget",IF(E39<0,"Under Budget","On Budget")) -> Over Budget
A40: =$A$38 -> July | B40: Benefits | C40: 30000 | D40: 30950 | E40: =D40-C40 -> 950 | F40: =IFERROR(E40/C40,0) -> 0.031666667 | G40: =IF(E40>0,"Over Budget",IF(E40<0,"Under Budget","On Budget")) -> Over Budget
...

Sheet Scenario Analysis
A1: Scenario Assumptions | G1: Scenario | H1: OT Reduction | I1: Salary Increase | J1: Tech Reduction | K1: Net Savings | L1: Risk Level | M1: Projected Annual Spending | N1: Variance to Budget
A2: Overtime Reduction Target | B2: 0.5 | G2: Cost-Neutral Compensation | H2: 0.5 | I2: =($B$7*H2+$B$9*J2)/$B$8 -> 0.062122433 | J2: 0 | K2: 0 | L2: Requires Capacity Review | M2: ='Budget Vs Actual'!$K$7-'Scenario Analysis'!K2 -> 2557425 | N2: =M2-Assumptions!$B$2 -> 157425
A3: Expected Salary Increase | B3: 0.062122433 | G3: Balanced Compensation | H3: 0.35 | I3: 0.05 | J3: 0.05 | K3: =$B$7*H2-$B$8*I2+$B$9*J2 -> 0 | L3: Requires Capacity Review | M3: ='Budget Vs Actual'!$K$7-'Scenario Analysis'!K3 -> 2557425 | N3: =M3-Assumptions!$B$2 -> 157425
A4: Technology Cost Reduction | B4: 0 | G4: Aggressive Compensation | H4: 0.805 | I4: 0.1 | J4: 0 | K4: =$B$7*H4-$B$8*I4+$B$9*J4 -> 25.5 | L4: High - Capacity Risk | M4: ='Budget Vs Actual'!$K$7-'Scenario Analysis'!K4 -> 2557399.5 | N4: =M4-Assumptions!$B$2 -> 157399.5
A6: Expense Category | B6: Current Spending | C6: Adjustments ($) | D6: Projected Spending | E6: Savings/(Additional Cost)
A7: Overtime | B7: =SUMIF('Budget Vs Actual'!$I$2:$I$6,'Scenario Analysis'!A7,'Budget Vs Actual'!$K$2:$K$6) -> 185100 | C7: =-B2 -> -0.5 | D7: =B7*(1+C7) -> 92550 | E7: =B7-D7 -> 92550
A8: Salaries and Wages | B8: =SUMIF('Budget Vs Actual'!$I$2:$I$6,'Scenario Analysis'!A8,'Budget Vs Actual'!$K$2:$K$6) -> 1489800 | C8: =B3 -> 0.062122433 | D8: =B8*(1+C8) -> 1582350 | E8: =B8-D8 -> -92550
A9: Technology | B9: =SUMIF('Budget Vs Actual'!$I$2:$I$6,'Scenario Analysis'!A9,'Budget Vs Actual'!$K$2:$K$6) -> 256150 | C9: =-B4 -> 0 | D9: =B9*(1+C9) -> 256150 | E9: =B9-D9 -> 0
D10: Total | E10: =SUM(E7:E9) -> -4.6566129e-10

Sheet Resource Planning
A1: Planning Assumption | B1: Value
A2: Current Employees | B2: 30
A3: Weekly Hours per Employee | B3: 40
A4: Paid Weeks per Year | B4: 52
A5: Productive Availability | B5: 0.8
A6: Annual Workload Hours | B6: 65000
A8: Annual Paid Hours | B8: =B2*B3*B4 -> 62400
A9: Annual Productive Hours | B9: =B8*B5 -> 49920
A10: Workload Gap (Hours) | B10: =B6-B9 -> 15080
A11: Additional FTE Required | B11: =MAX(0,ROUNDUP(B10/(B3*B4*B5),0)) -> 10
A13: Annual Salary per Employee | B13: =Assumptions!B4/'Resource Planning'!B2 -> 48000
A14: Annual Salary + Benefits | B14: =B13*(1+Assumptions!B11) -> 60000
A15: Annual Cost of Additional Staff | B15: =B11*B14 -> 600000
A17: Estimated Overtime Hourly Rate | B17: =(B13/(B3*B4)*1.5) -> 34.615385
A18: Overtime Hours Funded | B18: ='Budget Vs Actual'!K2/'Resource Planning'!B17 -> 5347.3333
A19: Productive Overtime Hours | B19: =B18*B5 -> 4277.8667
A20: Remaining Productive Hours Gap | B20: =MAX(0,B10-B19) -> 10802.133
A21: Additional FTE After Overtime | B21: =ROUNDUP(B20/(B3*B4*B5),0) -> 7

Sheet Executive Dashboard
A1: 2026 Business Operations
A2: Budget Performance | Executive Dashboard
A56: 2026 Financial Scenario Comparison
A57: ='Scenario Analysis'!G1 -> Scenario | C57: ='Scenario Analysis'!H1 -> OT Reduction | E57: ='Scenario Analysis'!I1 -> Salary Increase | G57: ='Scenario Analysis'!K1 -> Net Savings | I57: ='Scenario Analysis'!M1 -> Projected Annual Spending
A58: ='Scenario Analysis'!G2 -> Cost-Neutral Compensation | C58: ='Scenario Analysis'!H2 -> 0.5 | E58: ='Scenario Analysis'!I2 -> 0.062122433 | G58: ='Scenario Analysis'!K2 -> 0 | I58: ='Scenario Analysis'!M2 -> 2557425
A59: ='Scenario Analysis'!G3 -> Balanced Compensation | C59: ='Scenario Analysis'!H3 -> 0.35 | E59: ='Scenario Analysis'!I3 -> 0.05 | G59: ='Scenario Analysis'!K3 -> 0 | I59: ='Scenario Analysis'!M3 -> 2557425
A60: ='Scenario Analysis'!G4 -> Aggressive Compensation | C60: ='Scenario Analysis'!H4 -> 0.805 | E60: ='Scenario Analysis'!I4 -> 0.1 | G60: ='Scenario Analysis'!K4 -> 25.5 | I60: ='Scenario Analysis'!M4 -> 2557399.5
A61: Management Findings and Recommendations
A62: RESOURCE PLANNING FINDINGS Staffing Capacity: The department's 30 employees provide approximately 49,920 productive hours annually, compared with 65,000 hours of modeled workload demand. Overtime Capacity: Existing overtime spending covers approximately 4,278 additional productive hours, leaving an estimated shortfall of 10,802 hours. Resource Requirements: Approximately seven additional full-time employees would be needed to cover the remaining workload under the model's assumptions. Management Recommendation: Review staffing levels, workload distribution, and overtime utilization before implementing proposed overtime reductions. Although compensation-reallocation scenarios offer potential financial benefits, the current resource model suggests those reductions would increase the staffing gap unless additional capacity or efficiency improvements are introduced. *All figures are simulated planning estimates, not actual company operating results.*
A64: All data is simulated. Overtime-reduction scenarios are hypothetical and require staffing capacity validation before implementation.
